Workbook

Sheet NFC Score
A1: Date | B1: Number | C1: Title | D1: Liked | E1: Okay | F1: Disliked | G1: Aproko FC | H1: No of votes | I1: NFC Score
A2: 44976 | B2: =IF(B1="Number",1,B1+1) -> 1 | C2: A Sunday Affair | D2: 0.082 | E2: 0.205 | F2: 0.434 | G2: 0.279 | H2: 122 | I2: =IF(E2="N/A","N/A",(ROUND(D2*H2,0)*10/($H2*(1-$G2)*10))+(ROUND(E2*H2,0)*5/($H2*(1-$G2)*10))) -> 0.25579227
A3: 44990 | B3: =IF(B2="Number",1,B2+1) -> 2 | C3: Here Love Lies | D3: 0.132 | E3: 0.132 | F3: 0.245 | G3: 0.491 | H3: 53 | I3: =IF(E3="N/A","N/A",(ROUND(D3*H3,0)*10/($H3*(1-$G3)*10))+(ROUND(E3*H3,0)*5/($H3*(1-$G3)*10))) -> 0.38922045
A4: 44997 | B4: =IF(B3="Number",1,B3+1) -> 3 | C4: Jolly Roger | D4: 0.184 | E4: 0.204 | F4: 0.265 | G4: 0.347 | H4: 49 | I4: =IF(E4="N/A","N/A",(ROUND(D4*H4,0)*10/($H4*(1-$G4)*10))+(ROUND(E4*H4,0)*5/($H4*(1-$G4)*10))) -> 0.43754102
A5: 45004 | B5: =IF(B4="Number",1,B4+1) -> 4 | C5: The Trade | D5: 0.655 | E5: 0.138 | F5: 0.034 | G5: 0.172 | H5: 145 | I5: =IF(E5="N/A","N/A",(ROUND(D5*H5,0)*10/($H5*(1-$G5)*10))+(ROUND(E5*H5,0)*5/($H5*(1-$G5)*10))) -> 0.87456272
A6: 45004 | B6: =IF(B5="Number",1,B5+1) -> 5 | C6: The Trade | D6: 0.4 | E6: 0.292 | F6: 0.077 | G6: 0.231 | H6: 65 | I6: =IF(E6="N/A","N/A",(ROUND(D6*H6,0)*10/($H6*(1-$G6)*10))+(ROUND(E6*H6,0)*5/($H6*(1-$G6)*10))) -> 0.71021306
A7: 45018 | B7: =IF(B6="Number",1,B6+1) -> 6 | C7: African Folktales Reimagined | D7: 0.283 | E7: 0.217 | F7: 0.067 | G7: 0.433 | H7: 60 | I7: =IF(E7="N/A","N/A",(ROUND(D7*H7,0)*10/($H7*(1-$G7)*10))+(ROUND(E7*H7,0)*5/($H7*(1-$G7)*10))) -> 0.69077014
A8: 45025 | B8: =IF(B7="Number",1,B7+1) -> 7 | C8: Gangs Of Lagos | D8: 0.47 | E8: 0.277 | F8: 0.06 | G8: 0.193 | H8: 83 | I8: =IF(E8="N/A","N/A",(ROUND(D8*H8,0)*10/($H8*(1-$G8)*10))+(ROUND(E8*H8,0)*5/($H8*(1-$G8)*10))) -> 0.75394515
A9: 45046 | B9: =IF(B8="Number",1,B8+1) -> 8 | C9: A Simple Lie | D9: 0.279 | E9: 0.233 | F9: 0.372 | G9: 0.116 | H9: 43 | I9: =IF(E9="N/A","N/A",(ROUND(D9*H9,0)*10/($H9*(1-$G9)*10))+(ROUND(E9*H9,0)*5/($H9*(1-$G9)*10))) -> 0.44722719
A10: 45053 | B10: =IF(B9="Number",1,B9+1) -> 9 | C10: The Order Of Things | D10: 0.061 | E10: 0.184 | F10: 0.388 | G10: 0.367 | H10: 98 | I10: =IF(E10="N/A","N/A",(ROUND(D10*H10,0)*10/($H10*(1-$G10)*10))+(ROUND(E10*H10,0)*5/($H10*(1-$G10)*10))) -> 0.24180288
A11: 45060 | B11: =IF(B10="Number",1,B10+1) -> 10 | C11: Samaria | D11: 0.267 | E11: 0.133 | F11: 0.156 | G11: 0.444 | H11: 45 | I11: =IF(E11="N/A","N/A",(ROUND(D11*H11,0)*10/($H11*(1-$G11)*10))+(ROUND(E11*H11,0)*5/($H11*(1-$G11)*10))) -> 0.59952038
A12: 45060 | B12: =IF(B11="Number",1,B11+1) -> 11 | C12: The Way Things Happen | D12: 0.571 | E12: 0.107 | F12: 0.143 | G12: 0.179 | H12: 28 | I12: =IF(E12="N/A","N/A",(ROUND(D12*H12,0)*10/($H12*(1-$G12)*10))+(ROUND(E12*H12,0)*5/($H12*(1-$G12)*10))) -> 0.76126675
A13: 45067 | B13: =IF(B12="Number",1,B12+1) -> 12 | C13: Ile Owo | D13: 0.087 | E13: 0.217 | F13: 0.365 | G13: 0.33 | H13: 115 | I13: =IF(E13="N/A","N/A",(ROUND(D13*H13,0)*10/($H13*(1-$G13)*10))+(ROUND(E13*H13,0)*5/($H13*(1-$G13)*10))) -> 0.29201817
... A37: 45277 | B37: =IF(B36="Number",1,B36+1) -> 36 | C37: Breath Of Life | D37: 0.471 | E37: 0.235 | F37: 0.092 | G37: 0.202 | H37: 119 | I37: =IF(E37="N/A","N/A",(ROUND(D37*H37,0)*10/($H37*(1-$G37)*10))+(ROUND(E37*H37,0)*5/($H37*(1-$G37)*10))) -> 0.73713696
A38: 45543 | B38: =IF(B37="Number",1,B37+1) -> 37 | C38: Love Notes | D38: N/A | E38: N/A | F38: N/A | G38: N/A | H38: N/A | I38: N/A
A39: 45333 | B39: =IF(B38="Number",1,B38+1) -> 38 | C39: The Meeting | D39: 0.667 | E39: 0.121 | F39: 0.015 | G39: 0.197 | H39: 66 | I39: =IF(E39="N/A","N/A",(ROUND(D39*H39,0)*10/($H39*(1-$G39)*10))+(ROUND(E39*H39,0)*5/($H39*(1-$G39)*10))) -> 0.90569455
A40: 45508 | B40: =IF(B39="Number",1,B39+1) -> 39 | C40: With Difficulty Comes Ease | D40: 0.468 | E40: 0.096 | F40: 0.032 | G40: 0.404 | H40: 94 | I40: =IF(E40="N/A","N/A",(ROUND(D40*H40,0)*10/($H40*(1-$G40)*10))+(ROUND(E40*H40,0)*5/($H40*(1-$G40)*10))) -> 0.86570041
A41: 45347 | B41: =IF(B40="Number",1,B40+1) -> 40 | C41: Phone Swap | D41: 0.505 | E41: 0.253 | F41: 0.021 | G41: 0.221 | H41: 95 | I41: =IF(E41="N/A","N/A",(ROUND(D41*H41,0)*10/($H41*(1-$G41)*10))+(ROUND(E41*H41,0)*5/($H41*(1-$G41)*10))) -> 0.81075603
A42: 45382 | B42: =IF(B41="Number",1,B41+1) -> 41 | C42: Afamefuna | D42: 0.529 | E42: 0.187 | F42: 0.077 | G42: 0.206 | H42: 155 | I42: =IF(E42="N/A","N/A",(ROUND(D42*H42,0)*10/($H42*(1-$G42)*10))+(ROUND(E42*H42,0)*5/($H42*(1-$G42)*10))) -> 0.78410661
A43: 45466 | B43: =IF(B42="Number",1,B42+1) -> 42 | C43: Funmilayo Ransome Kuti | D43: 0.348 | E43: 0.227 | F43: 0.061 | G43: 0.364 | H43: 66 | I43: =IF(E43="N/A","N/A",(ROUND(D43*H43,0)*10/($H43*(1-$G43)*10))+(ROUND(E43*H43,0)*5/($H43*(1-$G43)*10))) -> 0.72660568
A44: 45445 | B44: =IF(B43="Number",1,B43+1) -> 43 | C44: Kill Boro | D44: 0.367 | E44: 0.178 | F44: 0.078 | G44: 0.378 | H44: 80 | I44: =IF(E44="N/A","N/A",(ROUND(D44*H44,0)*10/($H44*(1-$G44)*10))+(ROUND(E44*H44,0)*5/($H44*(1-$G44)*10))) -> 0.72347267
A45: 45452 | B45: =IF(B44="Number",1,B44+1) -> 44 | C45: A Father's Love | D45: 0.315 | E45: 0.26 | F45: 0.068 | G45: 0.356 | H45: 73 | I45: =IF(E45="N/A","N/A",(ROUND(D45*H45,0)*10/($H45*(1-$G45)*10))+(ROUND(E45*H45,0)*5/($H45*(1-$G45)*10))) -> 0.69131286
A46: 45403 | B46: =IF(B45="Number",1,B45+1) -> 45 | C46: A Tribe Called Judah | D46: 0.412 | E46: 0.221 | F46: 0.137 | G46: 0.229 | H46: 131 | I46: =IF(E46="N/A","N/A",(ROUND(D46*H46,0)*10/($H46*(1-$G46)*10))+(ROUND(E46*H46,0)*5/($H46*(1-$G46)*10))) -> 0.67821111
A47: 45627 | B47: =IF(B46="Number",1,B46+1) -> 46 | C47: Suspicion | D47: 0.33 | E47: 0.16 | F47: 0.117 | G47: 0.394 | H47: 94 | I47: =IF(E47="N/A","N/A",(ROUND(D47*H47,0)*10/($H47*(1-$G47)*10))+(ROUND(E47*H47,0)*5/($H47*(1-$G47)*10))) -> 0.67586546
A48: 45305 | B48: =IF(B47="Number",1,B47+1) -> 47 | C48: Adire | D48: 0.338 | E48: 0.299 | F48: 0.117 | G48: 0.247 | H48: 77 | I48: =IF(E48="N/A","N/A",(ROUND(D48*H48,0)*10/($H48*(1-$G48)*10))+(ROUND(E48*H48,0)*5/($H48*(1-$G48)*10))) -> 0.64676359
A49: 45501 | B49: =IF(B48="Number",1,B48+1) -> 48 | C49: House Of Ga'a | D49: 0.25 | E49: 0.25 | F49: 0.133 | G49: 0.367 | H49: 60 | I49: =IF(E49="N/A","N/A",(ROUND(D49*H49,0)*10/($H49*(1-$G49)*10))+(ROUND(E49*H49,0)*5/($H49*(1-$G49)*10))) -> 0.59241706
A50: 45410 | B50: =IF(B49="Number",1,B49+1) -> 49 | C50: Strained | D50: 0.167 | E50: 0.212 | F50: 0.152 | G50: 0.47 | H50: 66 | I50: =IF(E50="N/A","N/A",(ROUND(D50*H50,0)*10/($H50*(1-$G50)*10))+(ROUND(E50*H50,0)*5/($H50*(1-$G50)*10))) -> 0.51457976
... A71: 45648 | B71: =IF(B70="Number",1,B70+1) -> 70 | C71: Christmas In Lagos | D71: 0.3 | E71: 0.258 | F71: 0.233 | G71: 0.208 | H71: 120 | I71: =IF(E71="N/A","N/A",(ROUND(D71*H71,0)*10/($H71*(1-$G71)*10))+(ROUND(E71*H71,0)*5/($H71*(1-$G71)*10))) -> 0.5418771
A72: =INDEX('NFC All time'!D:D,MATCH(C72,'NFC All time'!C:C,0)) -> 45732 | B72: =IF(B71="Number",1,B71+1) -> 71 | C72: Finding Me | I72: =IFERROR(IF(E72="N/A","N/A",(ROUND(D72*H72,0)*10/($H72*(1-$G72)*10))+(ROUND(E72*H72,0)*5/($H72*(1-$G72)*10))),"Mr C Forgot") -> Mr C Forgot
A73: =INDEX('NFC All time'!D:D,MATCH(C73,'NFC All time'!C:C,0)) -> 45739 | B73: =IF(B72="Number",1,B72+1) -> 72 | C73: Suky | I73: =IFERROR(IF(E73="N/A","N/A",(ROUND(D73*H73,0)*10/($H73*(1-$G73)*10))+(ROUND(E73*H73,0)*5/($H73*(1-$G73)*10))),"Mr C Forgot") -> Mr C Forgot
A74: =INDEX('NFC All time'!D:D,MATCH(C74,'NFC All time'!C:C,0)) -> 45774 | B74: =IF(B73="Number",1,B73+1) -> 73 | C74: A Lagos Love Story | D74: 0.112 | E74: 0.203 | F74: 0.42 | G74: 0.266 | H74: 143 | I74: =IFERROR(IF(E74="N/A","N/A",(ROUND(D74*H74,0)*10/($H74*(1-$G74)*10))+(ROUND(E74*H74,0)*5/($H74*(1-$G74)*10))),"Mr C Forgot") -> 0.29058135
A75: =INDEX('NFC All time'!D:D,MATCH(C75,'NFC All time'!C:C,0)) -> 45781 | B75: =IF(B74="Number",1,B74+1) -> 74 | C75: Landline | I75: =IFERROR(IF(E75="N/A","N/A",(ROUND(D75*H75,0)*10/($H75*(1-$G75)*10))+(ROUND(E75*H75,0)*5/($H75*(1-$G75)*10))),"Mr C Forgot") -> Mr C Forgot
A76: =INDEX('NFC All time'!D:D,MATCH(C76,'NFC All time'!C:C,0)) -> 45788 | B76: =IF(B75="Number",1,B75+1) -> 75 | C76: After 30 | D76: 0.119 | E76: 0.119 | F76: 0.343 | G76: 0.418 | H76: 67 | I76: =IFERROR(IF(E76="N/A","N/A",(ROUND(D76*H76,0)*10/($H76*(1-$G76)*10))+(ROUND(E76*H76,0)*5/($H76*(1-$G76)*10))),"Mr C Forgot") -> 0.30773965
A77: =INDEX('NFC All time'!D:D,MATCH(C77,'NFC All time'!C:C,0)) -> 45809 | B77: =IF(B76="Number",1,B76+1) -> 76 | C77: The Party | I77: =IFERROR(IF(E77="N/A","N/A",(ROUND(D77*H77,0)*10/($H77*(1-$G77)*10))+(ROUND(E77*H77,0)*5/($H77*(1-$G77)*10))),"Mr C Forgot") -> Mr C Forgot
A78: =INDEX('NFC All time'!D:D,MATCH(C78,'NFC All time'!C:C,0)) -> 45816 | B78: =IF(B77="Number",1,B77+1) -> 77 | C78: The Fire And The Moth | D78: 0.182 | E78: 0.197 | F78: 0.197 | G78: 0.424 | H78: 66 | I78: =IFERROR(IF(E78="N/A","N/A",(ROUND(D78*H78,0)*10/($H78*(1-$G78)*10))+(ROUND(E78*H78,0)*5/($H78*(1-$G78)*10))),"Mr C Forgot") -> 0.48663721
A79: =INDEX('NFC All time'!D:D,MATCH(C79,'NFC All time'!C:C,0)) -> 45830 | B79: =IF(B78="Number",1,B78+1) -> 78 | C79: Baby Farm | D79: 0.097 | E79: 0.323 | F79: 0.161 | G79: 0.419 | H79: 62 | I79: =IFERROR(IF(E79="N/A","N/A",(ROUND(D79*H79,0)*10/($H79*(1-$G79)*10))+(ROUND(E79*H79,0)*5/($H79*(1-$G79)*10))),"Mr C Forgot") -> 0.44417301
A80: =INDEX('NFC All time'!D:D,MATCH(C80,'NFC All time'!C:C,0)) -> 45837 | B80: =IF(B79="Number",1,B79+1) -> 79 | C80: Ms Kanyin | D80: 0.148 | E80: 0.25 | F80: 0.269 | G80: 0.333 | H80: 108 | I80: =IFERROR(IF(E80="N/A","N/A",(ROUND(D80*H80,0)*10/($H80*(1-$G80)*10))+(ROUND(E80*H80,0)*5/($H80*(1-$G80)*10))),"Mr C Forgot") -> 0.40951746
A81: =INDEX('NFC All time'!D:D,MATCH(C81,'NFC All time'!C:C,0)) -> 45851 | B81: =IF(B80="Number",1,B80+1) -> 80 | C81: The Lost Days | I81: =IFERROR(IF(E81="N/A","N/A",(ROUND(D81*H81,0)*10/($H81*(1-$G81)*10))+(ROUND(E81*H81,0)*5/($H81*(1-$G81)*10))),"Mr C Forgot") -> Mr C Forgot
A82: =INDEX('NFC All time'!D:D,MATCH(C82,'NFC All time'!C:C,0)) -> 45858 | B82: =IF(B81="Number",1,B81+1) -> 81 | C82: To Kill A Monkey | D82: 0.374 | E82: 0.263 | F82: 0.182 | G82: 0.182 | H82: 99 | I82: =IFERROR(IF(E82="N/A","N/A",(ROUND(D82*H82,0)*10/($H82*(1-$G82)*10))+(ROUND(E82*H82,0)*5/($H82*(1-$G82)*10))),"Mr C Forgot") -> 0.61742116

Sheet NFC All time
A1: Space # (All time) | B1: Space # (Year) | C1: Discussion | D1: Date | E1: Podcast #
A2: 1 | B2: =IFERROR(IF(G2<>"NFC",B1, IF(D2=D1,B1,IF(YEAR(D2)<>YEAR(D1),1,B1+1))),1) -> 1 | C2: This Lady Called Life | D2: 44318 | G2: NFC
A3: =IF(G3<>"NFC",A2,IF(D3=D2,A2,A2+1)) -> 2 | B3: =IFERROR(IF(G3<>"NFC",B2, IF(D3=D2,B2,IF(YEAR(D3)<>YEAR(D2),1,B2+1))),1) -> 2 | C3: Streaming Effects & Ojukokoro | D3: 44325 | F3: =A3-A2 -> 1 | G3: NFC
A4: =IF(G4<>"NFC",A3,IF(D4=D3,A3,A3+1)) -> 3 | B4: =IFERROR(IF(G4<>"NFC",B3, IF(D4=D3,B3,IF(YEAR(D4)<>YEAR(D3),1,B3+1))),1) -> 3 | C4: Nollywood Prediction & Seve | D4: 44332 | F4: =A4-A3 -> 1 | G4: NFC
A5: =IF(G5<>"NFC",A4,IF(D5=D4,A4,A4+1)) -> 4 | B5: =IFERROR(IF(G5<>"NFC",B4, IF(D5=D4,B4,IF(YEAR(D5)<>YEAR(D4),1,B4+1))),1) -> 4 | C5: I don't do nollywood | D5: 44339 | F5: =A5-A4 -> 1 | G5: NFC
A6: =IF(G6<>"NFC",A5,IF(D6=D5,A5,A5+1)) -> 5 | B6: =IFERROR(IF(G6<>"NFC",B5, IF(D6=D5,B5,IF(YEAR(D6)<>YEAR(D5),1,B5+1))),1) -> 5 | C6: Nollywood Favourites | D6: 44353 | F6: =A6-A5 -> 1 | G6: NFC
A7: =IF(G7<>"NFC",A6,IF(D7=D6,A6,A6+1)) -> 6 | B7: =IFERROR(IF(G7<>"NFC",B6, IF(D7=D6,B6,IF(YEAR(D7)<>YEAR(D6),1,B6+1))),1) -> 6 | C7: Rattlesnake : The Ahanna Story | D7: 44388 | F7: =A7-A6 -> 1 | G7: NFC
A8: =IF(G8<>"NFC",A7,IF(D8=D7,A7,A7+1)) -> 7 | B8: =IFERROR(IF(G8<>"NFC",B7, IF(D8=D7,B7,IF(YEAR(D8)<>YEAR(D7),1,B7+1))),1) -> 7 | C8: Day Of Destiny | D8: 44395 | F8: =A8-A7 -> 1 | G8: NFC
A9: =IF(G9<>"NFC",A8,IF(D9=D8,A8,A8+1)) -> 8 | B9: =IFERROR(IF(G9<>"NFC",B8, IF(D9=D8,B8,IF(YEAR(D9)<>YEAR(D8),1,B8+1))),1) -> 8 | C9: Day Of Destiny & King Of Boy: | D9: 44409 | F9: =A9-A8 -> 1 | G9: NFC
A10: =IF(G10<>"NFC",A9,IF(D10=D9,A9,A9+1)) -> 9 | B10: =IFERROR(IF(G10<>"NFC",B9, IF(D10=D9,B9,IF(YEAR(D10)<>YEAR(D9),1,B9+1))),1) -> 9 | C10: lje | D10: 44416 | F10: =A10-A9 -> 1 | G10: NFC
A11: =IF(G11<>"NFC",A10,IF(D11=D10,A10,A10+1)) -> 10 | B11: =IFERROR(IF(G11<>"NFC",B10, IF(D11=D10,B10,IF(YEAR(D11)<>YEAR(D10),1,B10+1))),1) -> 10 | C11: Nneka The Pretty Serpent | D11: 44430 | F11: =A11-A10 -> 1 | G11: NFC
A12: =IF(G12<>"NFC",A11,IF(D12=D11,A11,A11+1)) -> 11 | B12: =IFERROR(IF(G12<>"NFC",B11, IF(D12=D11,B11,IF(YEAR(D12)<>YEAR(D11),1,B11+1))),1) -> 11 | C12: King Of Boys Vol 2 | D12: 44437 | F12: =A12-A11 -> 1 | G12: NFC
A13: =IF(G13<>"NFC",A12,IF(D13=D12,A12,A12+1)) -> 12 | B13: =IFERROR(IF(G13<>"NFC",B12, IF(D13=D12,B12,IF(YEAR(D13)<>YEAR(D12),1,B12+1))),1) -> 12 | C13: Omo Ghetto | D13: 44451 | F13: =A13-A12 -> 1 | G13: NFC
A14: =IF(G14<>"NFC",A13,IF(D14=D13,A13,A13+1)) -> 13 | B14: =IFERROR(IF(G14<>"NFC",B13, IF(D14=D13,B13,IF(YEAR(D14)<>YEAR(D13),1,B13+1))),1) -> 13 | C14: Smart Money Woman | D14: 44465 | F14: =A14-A13 -> 1 | G14: NFC
A15: =IF(G15<>"NFC",A14,IF(D15=D14,A14,A14+1)) -> 14 | B15: =IFERROR(IF(G15<>"NFC",B14, IF(D15=D14,B14,IF(YEAR(D15)<>YEAR(D14),1,B14+1))),1) -> 14 | C15: Swallow | D15: 44479 | F15: =E16-E15 -> 0 | G15: NFC
A16: =IF(G16<>"NFC",A15,IF(D16=D15,A15,A15+1)) -> 15 | B16: =IFERROR(IF(G16<>"NFC",B15, IF(D16=D15,B15,IF(YEAR(D16)<>YEAR(D15),1,B15+1))),1) -> 15 | C16: Namaste Wahala & 76 | D16: 44493 | F16: =E17-E16 -> 0 | G16: NFC
A17: =IF(G17<>"NFC",A16,IF(D17=D16,A16,A16+1)) -> 16 | B17: =IFERROR(IF(G17<>"NFC",B16, IF(D17=D16,B16,IF(YEAR(D17)<>YEAR(D16),1,B16+1))),1) -> 16 | C17: Amina & Gone | D17: 44507 | F17: =E18-E17 -> 0 | G17: NFC
A18: =IF(G18<>"NFC",A17,IF(D18=D17,A17,A17+1)) -> 17 | B18: =IFERROR(IF(G18<>"NFC",B17, IF(D18=D17,B17,IF(YEAR(D18)<>YEAR(D17),1,B17+1))),1) -> 17 | C18: Oga Bolaji & Alter Ego | D18: 44521 | F18: =E19-E18 -> 0 | G18: NFC
A19: =IF(G19<>"NFC",A18,IF(D19=D18,A18,A18+1)) -> 18 | B19: =IFERROR(IF(G19<>"NFC",B18, IF(D19=D18,B18,IF(YEAR(D19)<>YEAR(D18),1,B18+1))),1) -> 18 | C19: La Femme Anjola | D19: 44535 | F19: =E20-E19 -> 0 | G19: NFC
A20: =IF(G20<>"NFC",A19,IF(D20=D19,A19,A19+1)) -> 19 | B20: =IFERROR(IF(G20<>"NFC",B19, IF(D20=D19,B19,IF(YEAR(D20)<>YEAR(D19),1,B19+1))),1) -> 19 | C20: A Naija Christmas | D20: 44549 | F20: =E21-E20 -> 0 | G20: NFC
A21: =IF(G21<>"NFC",A20,IF(D21=D20,A20,A20+1)) -> 20 | B21: =IFERROR(IF(G21<>"NFC",B20, IF(D21=D20,B20,IF(YEAR(D21)<>YEAR(D20),1,B20+1))),1) -> 1 | C21: Chief Daddy 2 | D21: 44570 | F21: =E22-E21 -> 0 | G21: NFC
A22: =IF(G22<>"NFC",A21,IF(D22=D21,A21,A21+1)) -> 21 | B22: =IFERROR(IF(G22<>"NFC",B21, IF(D22=D21,B21,IF(YEAR(D22)<>YEAR(D21),1,B21+1))),1) -> 2 | C22: Juju Stories | D22: 44584 | F22: =E23-E22 -> 0 | G22: NFC
A23: =IF(G23<>"NFC",A22,IF(D23=D22,A22,A22+1)) -> 22 | B23: =IFERROR(IF(G23<>"NFC",B22, IF(D23=D22,B22,IF(YEAR(D23)<>YEAR(D22),1,B22+1))),1) -> 3 | C23: NollyFight #0 | D23: 44598 | F23: =E24-E23 -> 0 | G23: NFC
A24: =IF(G24<>"NFC",A23,IF(D24=D23,A23,A23+1)) -> 23 | B24: =IFERROR(IF(G24<>"NFC",B23, IF(D24=D23,B23,IF(YEAR(D24)<>YEAR(D23),1,B23+1))),1) -> 4 | C24: Isoken | D24: 44605 | F24: =E25-E24 -> 0 | G24: NFC
A25: =IF(G25<>"NFC",A24,IF(D25=D24,A24,A24+1)) -> 24 | B25: =IFERROR(IF(G25<>"NFC",B24, IF(D25=D24,B24,IF(YEAR(D25)<>YEAR(D24),1,B24+1))),1) -> 5 | C25: Falling | D25: 44612 | F25: =E26-E25 -> 0 | G25: NFC
A26: =IF(G26<>"NFC",A25,IF(D26=D25,A25,A25+1)) -> 25 | B26: =IFERROR(IF(G26<>"NFC",B25, IF(D26=D25,B25,IF(YEAR(D26)<>YEAR(D25),1,B25+1))),1) -> 6 | C26: Flower Girl | D26: 44619 | F26: =E27-E26 -> 0 | G26: NFC
... A44: =IF(G44<>"NFC",A43,IF(D44=D43,A43,A43+1)) -> 43 | B44: =IFERROR(IF(G44<>"NFC",B43, IF(D44=D43,B43,IF(YEAR(D44)<>YEAR(D43),1,B43+1))),1) -> 24 | C44: Something Special | D44: 44745 | F44: =E45-E44 -> 1 | G44: NFC
A45: =IF(G45<>"NFC",A44,IF(D45=D44,A44,A44+1)) -> 44 | B45: =IFERROR(IF(G45<>"NFC",B44, IF(D45=D44,B44,IF(YEAR(D45)<>YEAR(D44),1,B44+1))),1) -> 25 | C45: Prophetess | D45: 44752 | E45: 1 | F45: =E45-E44 -> 1 | G45: NFC
A46: =IF(G46<>"NFC",A45,IF(D46=D45,A45,A45+1)) -> 45 | B46: =IFERROR(IF(G46<>"NFC",B45, IF(D46=D45,B45,IF(YEAR(D46)<>YEAR(D45),1,B45+1))),1) -> 26 | C46: The Blood Covenant | D46: 44759 | E46: =IF(OR(D46=D45,G46<>"NFC"),E45,E45+1) -> 2 | F46: =E46-E45 -> 1 | G46: NFC
A47: =IF(G47<>"NFC",A46,IF(D47=D46,A46,A46+1)) -> 46 | B47: =IFERROR(IF(G47<>"NFC",B46, IF(D47=D46,B46,IF(YEAR(D47)<>YEAR(D46),1,B46+1))),1) -> 27 | C47: Village People | D47: 44766 | E47: =IF(OR(D47=D46,G47<>"NFC"),E46,E46+1) -> 3 | F47: =E47-E46 -> 1 | G47: NFC
A48: =IF(G48<>"NFC",A47,IF(D48=D47,A47,A47+1)) -> 46 | B48: =IFERROR(IF(G48<>"NFC",B47, IF(D48=D47,B47,IF(YEAR(D48)<>YEAR(D47),1,B47+1))),1) -> 27 | C48: Mildred, Precious & Tosin dis | D48: 44770 | E48: =IF(OR(D48=D47,G48<>"NFC"),E47,E47+1) -> 3 | F48: =E48-E47 -> 0 | G48: =TEXT(D48,"DDD") -> Thu
A49: =IF(G49<>"NFC",A48,IF(D49=D48,A48,A48+1)) -> 47 | B49: =IFERROR(IF(G49<>"NFC",B48, IF(D49=D48,B48,IF(YEAR(D49)<>YEAR(D48),1,B48+1))),1) -> 28 | C49: The Perfect Arrangement | D49: 44773 | E49: =IF(OR(D49=D48,G49<>"NFC"),E48,E48+1) -> 4 | F49: =E49-E48 -> 1 | G49: NFC
A50: =IF(G50<>"NFC",A49,IF(D50=D49,A49,A49+1)) -> 48 | B50: =IFERROR(IF(G50<>"NFC",B49, IF(D50=D49,B49,IF(YEAR(D50)<>YEAR(D49),1,B49+1))),1) -> 29 | C50: Lockdown | D50: 44780 | E50: =IF(OR(D50=D49,G50<>"NFC"),E49,E49+1) -> 5 | F50: =E50-E49 -> 1 | G50: NFC
A51: =IF(G51<>"NFC",A50,IF(D51=D50,A50,A50+1)) -> 49 | B51: =IFERROR(IF(G51<>"NFC",B50, IF(D51=D50,B50,IF(YEAR(D51)<>YEAR(D50),1,B50+1))),1) -> 30 | C51: The Razz Guy | D51: 44787 | E51: =IF(OR(D51=D50,G51<>"NFC"),E50,E50+1) -> 6 | F51: =E51-E50 -> 1 | G51: NFC
A52: =IF(G52<>"NFC",A51,IF(D52=D51,A51,A51+1)) -> 50 | B52: =IFERROR(IF(G52<>"NFC",B51, IF(D52=D51,B51,IF(YEAR(D52)<>YEAR(D51),1,B51+1))),1) -> 31 | C52: Dwindle | D52: 44794 | E52: =IF(OR(D52=D51,G52<>"NFC"),E51,E51+1) -> 7 | F52: =E52-E51 -> 1 | G52: NFC
A53: =IF(G53<>"NFC",A52,IF(D53=D52,A52,A52+1)) -> 51 | B53: =IFERROR(IF(G53<>"NFC",B52, IF(D53=D52,B52,IF(YEAR(D53)<>YEAR(D52),1,B52+1))),1) -> 32 | C53: King Of Thieves | D53: 44801 | E53: =IF(OR(D53=D52,G53<>"NFC"),E52,E52+1) -> 8 | F53: =E53-E52 -> 1 | G53: NFC
A54: =IF(G54<>"NFC",A53,IF(D54=D53,A53,A53+1)) -> 51 | B54: =IFERROR(IF(G54<>"NFC",B53, IF(D54=D53,B53,IF(YEAR(D54)<>YEAR(D53),1,B53+1))),1) -> 32 | C54: The Razz Guy QnA | D54: 44806 | E54: =IF(OR(D54=D53,G54<>"NFC"),E53,E53+1) -> 8 | F54: =E54-E53 -> 0 | G54: =TEXT(D54,"DDD") -> Fri
A55: =IF(G55<>"NFC",A54,IF(D55=D54,A54,A54+1)) -> 52 | B55: =IFERROR(IF(G55<>"NFC",B54, IF(D55=D54,B54,IF(YEAR(D55)<>YEAR(D54),1,B54+1))),1) -> 33 | C55: Collision Course | D55: 44808 | E55: =IF(OR(D55=D54,G55<>"NFC"),E54,E54+1) -> 9 | F55: =E55-E54 -> 1 | G55: NFC
A56: =IF(G56<>"NFC",A55,IF(D56=D55,A55,A55+1)) -> 53 | B56: =IFERROR(IF(G56<>"NFC",B55, IF(D56=D55,B55,IF(YEAR(D56)<>YEAR(D55),1,B55+1))),1) -> 34 | C56: Fine Wine | D56: 44815 | E56: =IF(OR(D56=D55,G56<>"NFC"),E55,E55+1) -> 10 | F56: =E56-E55 -> 1 | G56: NFC
A57: =IF(G57<>"NFC",A56,IF(D57=D56,A56,A56+1)) -> 54 | B57: =IFERROR(IF(G57<>"NFC",B56, IF(D57=D56,B56,IF(YEAR(D57)<>YEAR(D56),1,B56+1))),1) -> 35 | C57: The Man For The Job | D57: 44822 | E57: =IF(OR(D57=D56,G57<>"NFC"),E56,E56+1) -> 11 | F57: =E57-E56 -> 1 | G57: NFC
...
